Workbook

Sheet Opponents
A1: Opponent (as in data) | B1: Suggested merged name | C1: Total | D1: Home | E1: Away | F1: Neutral | G1: First away | H1: Last away | I1: Away seasons | J1: Ground notes (from general knowledge — verify)
A2: 1.FC Köln | B2: 1.FC Köln | C2: =COUNTIF(Fixtures!$H$2:$H$2102,A2) -> 2 | D2: =COUNTIFS(Fixtures!$H$2:$H$2102,A2,Fixtures!$I$2:$I$2102,"H") -> 1 | E2: =COUNTIFS(Fixtures!$H$2:$H$2102,A2,Fixtures!$I$2:$I$2102,"A") -> 1 | F2: =COUNTIFS(Fixtures!$H$2:$H$2102,A2,Fixtures!$I$2:$I$2102,"N") -> 0 | G2: =IF(E2=0,"",_xlfn.MINIFS(Fixtures!$A$2:$A$2102,Fixtures!$H$2:$H$2102,A2,Fixtures!$I$2:$I$2102,"A")) -> 43062 | H2: =IF(E2=0,"",_xlfn.MAXIFS(Fixtures!$A$2:$A$2102,Fixtures!$H$2:$H$2102,A2,Fixtures!$I$2:$I$2102,"A")) -> 43062 | I2: 2017/18
A3: AC Milan | B3: AC Milan | C3: =COUNTIF(Fixtures!$H$2:$H$2102,A3) -> 8 | D3: =COUNTIFS(Fixtures!$H$2:$H$2102,A3,Fixtures!$I$2:$I$2102,"H") -> 4 | E3: =COUNTIFS(Fixtures!$H$2:$H$2102,A3,Fixtures!$I$2:$I$2102,"A") -> 4 | F3: =COUNTIFS(Fixtures!$H$2:$H$2102,A3,Fixtures!$I$2:$I$2102,"N") -> 0 | G3: =IF(E3=0,"",_xlfn.MINIFS(Fixtures!$A$2:$A$2102,Fixtures!$H$2:$H$2102,A3,Fixtures!$I$2:$I$2102,"A")) -> 34738 | H3: =IF(E3=0,"",_xlfn.MAXIFS(Fixtures!$A$2:$A$2102,Fixtures!$H$2:$H$2102,A3,Fixtures!$I$2:$I$2102,"A")) -> 43167 | I3: 1994/95, 2007/08, 2011/12, 2017/18
A4: AFC Bournemouth | B4: AFC Bournemouth | C4: =COUNTIF(Fixtures!$H$2:$H$2102,A4) -> 19 | D4: =COUNTIFS(Fixtures!$H$2:$H$2102,A4,Fixtures!$I$2:$I$2102,"H") -> 9 | E4: =COUNTIFS(Fixtures!$H$2:$H$2102,A4,Fixtures!$I$2:$I$2102,"A") -> 10 | F4: =COUNTIFS(Fixtures!$H$2:$H$2102,A4,Fixtures!$I$2:$I$2102,"N") -> 0 | G4: =IF(E4=0,"",_xlfn.MINIFS(Fixtures!$A$2:$A$2102,Fixtures!$H$2:$H$2102,A4,Fixtures!$I$2:$I$2102,"A")) -> 42407 | H4: =IF(E4=0,"",_xlfn.MAXIFS(Fixtures!$A$2:$A$2102,Fixtures!$H$2:$H$2102,A4,Fixtures!$I$2:$I$2102,"A")) -> 46025 | I4: 2015/16, 2016/17, 2017/18, 2018/19, 2019/20, 2022/23, 2023/24, 2024/25, 2025/26
A5: AFC Wimbledon | B5: AFC Wimbledon | C5: =COUNTIF(Fixtures!$H$2:$H$2102,A5) -> 1 | D5: =COUNTIFS(Fixtures!$H$2:$H$2102,A5,Fixtures!$I$2:$I$2102,"H") -> 1 | E5: =COUNTIFS(Fixtures!$H$2:$H$2102,A5,Fixtures!$I$2:$I$2102,"A") -> 0 | F5: =COUNTIFS(Fixtures!$H$2:$H$2102,A5,Fixtures!$I$2:$I$2102,"N") -> 0 | G5: =IF(E5=0,"",_xlfn.MINIFS(Fixtures!$A$2:$A$2102,Fixtures!$H$2:$H$2102,A5,Fixtures!$I$2:$I$2102,"A")) | H5: =IF(E5=0,"",_xlfn.MAXIFS(Fixtures!$A$2:$A$2102,Fixtures!$H$2:$H$2102,A5,Fixtures!$I$2:$I$2102,"A")) | J5: Different club from "Wimbledon" — keep separate.
A6: AIK Solna | B6: AIK Solna | C6: =COUNTIF(Fixtures!$H$2:$H$2102,A6) -> 2 | D6: =COUNTIFS(Fixtures!$H$2:$H$2102,A6,Fixtures!$I$2:$I$2102,"H") -> 1 | E6: =COUNTIFS(Fixtures!$H$2:$H$2102,A6,Fixtures!$I$2:$I$2102,"A") -> 1 | F6: =COUNTIFS(Fixtures!$H$2:$H$2102,A6,Fixtures!$I$2:$I$2102,"N") -> 0 | G6: =IF(E6=0,"",_xlfn.MINIFS(Fixtures!$A$2:$A$2102,Fixtures!$H$2:$H$2102,A6,Fixtures!$I$2:$I$2102,"A")) -> 36466 | H6: =IF(E6=0,"",_xlfn.MAXIFS(Fixtures!$A$2:$A$2102,Fixtures!$H$2:$H$2102,A6,Fixtures!$I$2:$I$2102,"A")) -> 36466 | I6: 1999/00
A7: Ajax | B7: Ajax | C7: =COUNTIF(Fixtures!$H$2:$H$2102,A7) -> 4 | D7: =COUNTIFS(Fixtures!$H$2:$H$2102,A7,Fixtures!$I$2:$I$2102,"H") -> 2 | E7: =COUNTIFS(Fixtures!$H$2:$H$2102,A7,Fixtures!$I$2:$I$2102,"A") -> 2 | F7: =COUNTIFS(Fixtures!$H$2:$H$2102,A7,Fixtures!$I$2:$I$2102,"N") -> 0 | G7: =IF(E7=0,"",_xlfn.MINIFS(Fixtures!$A$2:$A$2102,Fixtures!$H$2:$H$2102,A7,Fixtures!$I$2:$I$2102,"A")) -> 37678 | H7: =IF(E7=0,"",_xlfn.MAXIFS(Fixtures!$A$2:$A$2102,Fixtures!$H$2:$H$2102,A7,Fixtures!$I$2:$I$2102,"A")) -> 38622 | I7: 2002/03, 2005/06
A8: Anderlecht | B8: Anderlecht | C8: =COUNTIF(Fixtures!$H$2:$H$2102,A8) -> 2 | D8: =COUNTIFS(Fixtures!$H$2:$H$2102,A8,Fixtures!$I$2:$I$2102,"H") -> 1 | E8: =COUNTIFS(Fixtures!$H$2:$H$2102,A8,Fixtures!$I$2:$I$2102,"A") -> 1 | F8: =COUNTIFS(Fixtures!$H$2:$H$2102,A8,Fixtures!$I$2:$I$2102,"N") -> 0 | G8: =IF(E8=0,"",_xlfn.MINIFS(Fixtures!$A$2:$A$2102,Fixtures!$H$2:$H$2102,A8,Fixtures!$I$2:$I$2102,"A")) -> 41934 | H8: =IF(E8=0,"",_xlfn.MAXIFS(Fixtures!$A$2:$A$2102,Fixtures!$H$2:$H$2102,A8,Fixtures!$I$2:$I$2102,"A")) -> 41934 | I8: 2014/15
A9: AS Monaco | B9: AS Monaco | C9: =COUNTIF(Fixtures!$H$2:$H$2102,A9) -> 3 | D9: =COUNTIFS(Fixtures!$H$2:$H$2102,A9,Fixtures!$I$2:$I$2102,"H") -> 2 | E9: =COUNTIFS(Fixtures!$H$2:$H$2102,A9,Fixtures!$I$2:$I$2102,"A") -> 1 | F9: =COUNTIFS(Fixtures!$H$2:$H$2102,A9,Fixtures!$I$2:$I$2102,"N") -> 0 | G9: =IF(E9=0,"",_xlfn.MINIFS(Fixtures!$A$2:$A$2102,Fixtures!$H$2:$H$2102,A9,Fixtures!$I$2:$I$2102,"A")) -> 42080 | H9: =IF(E9=0,"",_xlfn.MAXIFS(Fixtures!$A$2:$A$2102,Fixtures!$H$2:$H$2102,A9,Fixtures!$I$2:$I$2102,"A")) -> 42080 | I9: 2014/15
A10: AS Roma | B10: AS Roma | C10: =COUNTIF(Fixtures!$H$2:$H$2102,A10) -> 4 | D10: =COUNTIFS(Fixtures!$H$2:$H$2102,A10,Fixtures!$I$2:$I$2102,"H") -> 2 | E10: =COUNTIFS(Fixtures!$H$2:$H$2102,A10,Fixtures!$I$2:$I$2102,"A") -> 2 | F10: =COUNTIFS(Fixtures!$H$2:$H$2102,A10,Fixtures!$I$2:$I$2102,"N") -> 0 | G10: =IF(E10=0,"",_xlfn.MINIFS(Fixtures!$A$2:$A$2102,Fixtures!$H$2:$H$2102,A10,Fixtures!$I$2:$I$2102,"A")) -> 37587 | H10: =IF(E10=0,"",_xlfn.MAXIFS(Fixtures!$A$2:$A$2102,Fixtures!$H$2:$H$2102,A10,Fixtures!$I$2:$I$2102,"A")) -> 39883 | I10: 2002/03, 2008/09
A11: Aston Villa | B11: Aston Villa | C11: =COUNTIF(Fixtures!$H$2:$H$2102,A11) -> 75 | D11: =COUNTIFS(Fixtures!$H$2:$H$2102,A11,Fixtures!$I$2:$I$2102,"H") -> 38 | E11: =COUNTIFS(Fixtures!$H$2:$H$2102,A11,Fixtures!$I$2:$I$2102,"A") -> 36 | F11: =COUNTIFS(Fixtures!$H$2:$H$2102,A11,Fixtures!$I$2:$I$2102,"N") -> 1 | G11: =IF(E11=0,"",_xlfn.MINIFS(Fixtures!$A$2:$A$2102,Fixtures!$H$2:$H$2102,A11,Fixtures!$I$2:$I$2102,"A")) -> 32508 | H11: =IF(E11=0,"",_xlfn.MAXIFS(Fixtures!$A$2:$A$2102,Fixtures!$H$2:$H$2102,A11,Fixtures!$I$2:$I$2102,"A")) -> 45997 | I11: 1988/89, 1989/90, 1990/91, 1991/92, 1992/93, 1993/94, 1994/95, 1995/96, 1996/97, 1997/98, 1998/99, 1999/00, 2000/01, 2001/02, 2002/03, 2003/04, 2004/05, 2005/06, 2006/07, 2007/08, 2008/09, 2009/10, 2010/11, 2011/12, 2012/13, 2013/14, 2014/15, 2015/16, 2019/20, 2020/21, 2021/22, 2022/23, 2023/24, 2024/25, 2025/26
A12: Atalanta | B12: Atalanta | C12: =COUNTIF(Fixtures!$H$2:$H$2102,A12) -> 1 | D12: =COUNTIFS(Fixtures!$H$2:$H$2102,A12,Fixtures!$I$2:$I$2102,"H") -> 0 | E12: =COUNTIFS(Fixtures!$H$2:$H$2102,A12,Fixtures!$I$2:$I$2102,"A") -> 1 | F12: =COUNTIFS(Fixtures!$H$2:$H$2102,A12,Fixtures!$I$2:$I$2102,"N") -> 0 | G12: =IF(E12=0,"",_xlfn.MINIFS(Fixtures!$A$2:$A$2102,Fixtures!$H$2:$H$2102,A12,Fixtures!$I$2:$I$2102,"A")) -> 45554 | H12: =IF(E12=0,"",_xlfn.MAXIFS(Fixtures!$A$2:$A$2102,Fixtures!$H$2:$H$2102,A12,Fixtures!$I$2:$I$2102,"A")) -> 45554 | I12: 2024/25
A13: Athletic Bilbao | B13: Athletic Bilbao | C13: =COUNTIF(Fixtures!$H$2:$H$2102,A13) -> 1 | D13: =COUNTIFS(Fixtures!$H$2:$H$2102,A13,Fixtures!$I$2:$I$2102,"H") -> 0 | E13: =COUNTIFS(Fixtures!$H$2:$H$2102,A13,Fixtures!$I$2:$I$2102,"A") -> 1 | F13: =COUNTIFS(Fixtures!$H$2:$H$2102,A13,Fixtures!$I$2:$I$2102,"N") -> 0 | G13: =IF(E13=0,"",_xlfn.MINIFS(Fixtures!$A$2:$A$2102,Fixtures!$H$2:$H$2102,A13,Fixtures!$I$2:$I$2102,"A")) -> 45916 | H13: =IF(E13=0,"",_xlfn.MAXIFS(Fixtures!$A$2:$A$2102,Fixtures!$H$2:$H$2102,A13,Fixtures!$I$2:$I$2102,"A")) -> 45916 | I13: 2025/26
A14: Atletico Madrid | B14: Atletico Madrid | C14: =COUNTIF(Fixtures!$H$2:$H$2102,A14) -> 3 | D14: =COUNTIFS(Fixtures!$H$2:$H$2102,A14,Fixtures!$I$2:$I$2102,"H") -> 2 | E14: =COUNTIFS(Fixtures!$H$2:$H$2102,A14,Fixtures!$I$2:$I$2102,"A") -> 1 | F14: =COUNTIFS(Fixtures!$H$2:$H$2102,A14,Fixtures!$I$2:$I$2102,"N") -> 0 | G14: =IF(E14=0,"",_xlfn.MINIFS(Fixtures!$A$2:$A$2102,Fixtures!$H$2:$H$2102,A14,Fixtures!$I$2:$I$2102,"A")) -> 46141 | H14: =IF(E14=0,"",_xlfn.MAXIFS(Fixtures!$A$2:$A$2102,Fixtures!$H$2:$H$2102,A14,Fixtures!$I$2:$I$2102,"A")) -> 46141 | I14: 2025/26 | J14: Duplicate of "Atlético Madrid". Metropolitano for both away games here.
A15: Atlético Madrid | B15: Atletico Madrid | C15: =COUNTIF(Fixtures!$H$2:$H$2102,A15) -> 2 | D15: =COUNTIFS(Fixtures!$H$2:$H$2102,A15,Fixtures!$I$2:$I$2102,"H") -> 1 | E15: =COUNTIFS(Fixtures!$H$2:$H$2102,A15,Fixtures!$I$2:$I$2102,"A") -> 1 | F15: =COUNTIFS(Fixtures!$H$2:$H$2102,A15,Fixtures!$I$2:$I$2102,"N") -> 0 | G15: =IF(E15=0,"",_xlfn.MINIFS(Fixtures!$A$2:$A$2102,Fixtures!$H$2:$H$2102,A15,Fixtures!$I$2:$I$2102,"A")) -> 43223 | H15: =IF(E15=0,"",_xlfn.MAXIFS(Fixtures!$A$2:$A$2102,Fixtures!$H$2:$H$2102,A15,Fixtures!$I$2:$I$2102,"A")) -> 43223 | I15: 2017/18 | J15: See "Atletico Madrid" — duplicate name.
A16: Austria Wien | B16: Austria Wien | C16: =COUNTIF(Fixtures!$H$2:$H$2102,A16) -> 2 | D16: =COUNTIFS(Fixtures!$H$2:$H$2102,A16,Fixtures!$I$2:$I$2102,"H") -> 1 | E16: =COUNTIFS(Fixtures!$H$2:$H$2102,A16,Fixtures!$I$2:$I$2102,"A") -> 1 | F16: =COUNTIFS(Fixtures!$H$2:$H$2102,A16,Fixtures!$I$2:$I$2102,"N") -> 0 | G16: =IF(E16=0,"",_xlfn.MINIFS(Fixtures!$A$2:$A$2102,Fixtures!$H$2:$H$2102,A16,Fixtures!$I$2:$I$2102,"A")) -> 33513 | H16: =IF(E16=0,"",_xlfn.MAXIFS(Fixtures!$A$2:$A$2102,Fixtures!$H$2:$H$2102,A16,Fixtures!$I$2:$I$2102,"A")) -> 33513 | I16: 1991/92
A17: Auxerre | B17: Auxerre | C17: =COUNTIF(Fixtures!$H$2:$H$2102,A17) -> 4 | D17: =COUNTIFS(Fixtures!$H$2:$H$2102,A17,Fixtures!$I$2:$I$2102,"H") -> 2 | E17: =COUNTIFS(Fixtures!$H$2:$H$2102,A17,Fixtures!$I$2:$I$2102,"A") -> 2 | F17: =COUNTIFS(Fixtures!$H$2:$H$2102,A17,Fixtures!$I$2:$I$2102,"N") -> 0 | G17: =IF(E17=0,"",_xlfn.MINIFS(Fixtures!$A$2:$A$2102,Fixtures!$H$2:$H$2102,A17,Fixtures!$I$2:$I$2102,"A")) -> 34774 | H17: =IF(E17=0,"",_xlfn.MAXIFS(Fixtures!$A$2:$A$2102,Fixtures!$H$2:$H$2102,A17,Fixtures!$I$2:$I$2102,"A")) -> 37531 | I17: 1994/95, 2002/03
A18: AZ Alkmaar | B18: AZ Alkmaar | C18: =COUNTIF(Fixtures!$H$2:$H$2102,A18) -> 2 | D18: =COUNTIFS(Fixtures!$H$2:$H$2102,A18,Fixtures!$I$2:$I$2102,"H") -> 1 | E18: =COUNTIFS(Fixtures!$H$2:$H$2102,A18,Fixtures!$I$2:$I$2102,"A") -> 1 | F18: =COUNTIFS(Fixtures!$H$2:$H$2102,A18,Fixtures!$I$2:$I$2102,"N") -> 0 | G18: =IF(E18=0,"",_xlfn.MINIFS(Fixtures!$A$2:$A$2102,Fixtures!$H$2:$H$2102,A18,Fixtures!$I$2:$I$2102,"A")) -> 40106 | H18: =IF(E18=0,"",_xlfn.MAXIFS(Fixtures!$A$2:$A$2102,Fixtures!$H$2:$H$2102,A18,Fixtures!$I$2:$I$2102,"A")) -> 40106 | I18: 2009/10
A19: Barcelona | B19: Barcelona | C19: =COUNTIF(Fixtures!$H$2:$H$2102,A19) -> 9 | D19: =COUNTIFS(Fixtures!$H$2:$H$2102,A19,Fixtures!$I$2:$I$2102,"H") -> 4 | E19: =COUNTIFS(Fixtures!$H$2:$H$2102,A19,Fixtures!$I$2:$I$2102,"A") -> 4 | F19: =COUNTIFS(Fixtures!$H$2:$H$2102,A19,Fixtures!$I$2:$I$2102,"N") -> 1 | G19: =IF(E19=0,"",_xlfn.MINIFS(Fixtures!$A$2:$A$2102,Fixtures!$H$2:$H$2102,A19,Fixtures!$I$2:$I$2102,"A")) -> 36432 | H19: =IF(E19=0,"",_xlfn.MAXIFS(Fixtures!$A$2:$A$2102,Fixtures!$H$2:$H$2102,A19,Fixtures!$I$2:$I$2102,"A")) -> 42445 | I19: 1999/00, 2009/10, 2010/11, 2015/16 | J19: Camp Nou for all away games here. Arsenal's 1999/00 home game was at Wembley.
A20: Barnsley | B20: Barnsley | C20: =COUNTIF(Fixtures!$H$2:$H$2102,A20) -> 3 | D20: =COUNTIFS(Fixtures!$H$2:$H$2102,A20,Fixtures!$I$2:$I$2102,"H") -> 1 | E20: =COUNTIFS(Fixtures!$H$2:$H$2102,A20,Fixtures!$I$2:$I$2102,"A") -> 2 | F20: =COUNTIFS(Fixtures!$H$2:$H$2102,A20,Fixtures!$I$2:$I$2102,"N") -> 0 | G20: =IF(E20=0,"",_xlfn.MINIFS(Fixtures!$A$2:$A$2102,Fixtures!$H$2:$H$2102,A20,Fixtures!$I$2:$I$2102,"A")) -> 34996 | H20: =IF(E20=0,"",_xlfn.MAXIFS(Fixtures!$A$2:$A$2102,Fixtures!$H$2:$H$2102,A20,Fixtures!$I$2:$I$2102,"A")) -> 35910 | I20: 1995/96, 1997/98
A21: Bayer Leverkusen | B21: Bayer Leverkusen | C21: =COUNTIF(Fixtures!$H$2:$H$2102,A21) -> 4 | D21: =COUNTIFS(Fixtures!$H$2:$H$2102,A21,Fixtures!$I$2:$I$2102,"H") -> 2 | E21: =COUNTIFS(Fixtures!$H$2:$H$2102,A21,Fixtures!$I$2:$I$2102,"A") -> 2 | F21: =COUNTIFS(Fixtures!$H$2:$H$2102,A21,Fixtures!$I$2:$I$2102,"N") -> 0 | G21: =IF(E21=0,"",_xlfn.MINIFS(Fixtures!$A$2:$A$2102,Fixtures!$H$2:$H$2102,A21,Fixtures!$I$2:$I$2102,"A")) -> 37306 | H21: =IF(E21=0,"",_xlfn.MAXIFS(Fixtures!$A$2:$A$2102,Fixtures!$H$2:$H$2102,A21,Fixtures!$I$2:$I$2102,"A")) -> 46092 | I21: 2001/02, 2025/26
A22: Bayern Munchen | B22: Bayern Munchen | C22: =COUNTIF(Fixtures!$H$2:$H$2102,A22) -> 11 | D22: =COUNTIFS(Fixtures!$H$2:$H$2102,A22,Fixtures!$I$2:$I$2102,"H") -> 6 | E22: =COUNTIFS(Fixtures!$H$2:$H$2102,A22,Fixtures!$I$2:$I$2102,"A") -> 5 | F22: =COUNTIFS(Fixtures!$H$2:$H$2102,A22,Fixtures!$I$2:$I$2102,"N") -> 0 | G22: =IF(E22=0,"",_xlfn.MINIFS(Fixtures!$A$2:$A$2102,Fixtures!$H$2:$H$2102,A22,Fixtures!$I$2:$I$2102,"A")) -> 38405 | H22: =IF(E22=0,"",_xlfn.MAXIFS(Fixtures!$A$2:$A$2102,Fixtures!$H$2:$H$2102,A22,Fixtures!$I$2:$I$2102,"A")) -> 45399 | I22: 2004/05, 2012/13, 2013/14, 2015/16, 2023/24 | J22: Olympiastadion until 2004/05; Allianz Arena from 2005/06. Same club as "Bayern München".
A23: Bayern München | B23: Bayern Munchen | C23: =COUNTIF(Fixtures!$H$2:$H$2102,A23) -> 4 | D23: =COUNTIFS(Fixtures!$H$2:$H$2102,A23,Fixtures!$I$2:$I$2102,"H") -> 2 | E23: =COUNTIFS(Fixtures!$H$2:$H$2102,A23,Fixtures!$I$2:$I$2102,"A") -> 2 | F23: =COUNTIFS(Fixtures!$H$2:$H$2102,A23,Fixtures!$I$2:$I$2102,"N") -> 0 | G23: =IF(E23=0,"",_xlfn.MINIFS(Fixtures!$A$2:$A$2102,Fixtures!$H$2:$H$2102,A23,Fixtures!$I$2:$I$2102,"A")) -> 36964 | H23: =IF(E23=0,"",_xlfn.MAXIFS(Fixtures!$A$2:$A$2102,Fixtures!$H$2:$H$2102,A23,Fixtures!$I$2:$I$2102,"A")) -> 42781 | I23: 2000/01, 2016/17 | J23: See "Bayern Munchen" — duplicate name.
A24: Benfica | B24: Benfica | C24: =COUNTIF(Fixtures!$H$2:$H$2102,A24) -> 4 | D24: =COUNTIFS(Fixtures!$H$2:$H$2102,A24,Fixtures!$I$2:$I$2102,"H") -> 2 | E24: =COUNTIFS(Fixtures!$H$2:$H$2102,A24,Fixtures!$I$2:$I$2102,"A") -> 2 | F24: =COUNTIFS(Fixtures!$H$2:$H$2102,A24,Fixtures!$I$2:$I$2102,"N") -> 0 | G24: =IF(E24=0,"",_xlfn.MINIFS(Fixtures!$A$2:$A$2102,Fixtures!$H$2:$H$2102,A24,Fixtures!$I$2:$I$2102,"A")) -> 33534 | H24: =IF(E24=0,"",_xlfn.MAXIFS(Fixtures!$A$2:$A$2102,Fixtures!$H$2:$H$2102,A24,Fixtures!$I$2:$I$2102,"A")) -> 44245 | I24: 1991/92, 2020/21 | J24: 1991/92 at the old Estádio da Luz. 2020/21 "home" leg played in Rome (Stadio Olimpico).
A25: Besiktas | B25: Besiktas | C25: =COUNTIF(Fixtures!$H$2:$H$2102,A25) -> 2 | D25: =COUNTIFS(Fixtures!$H$2:$H$2102,A25,Fixtures!$I$2:$I$2102,"H") -> 1 | E25: =COUNTIFS(Fixtures!$H$2:$H$2102,A25,Fixtures!$I$2:$I$2102,"A") -> 1 | F25: =COUNTIFS(Fixtures!$H$2:$H$2102,A25,Fixtures!$I$2:$I$2102,"N") -> 0 | G25: =IF(E25=0,"",_xlfn.MINIFS(Fixtures!$A$2:$A$2102,Fixtures!$H$2:$H$2102,A25,Fixtures!$I$2:$I$2102,"A")) -> 41870 | H25: =IF(E25=0,"",_xlfn.MAXIFS(Fixtures!$A$2:$A$2102,Fixtures!$H$2:$H$2102,A25,Fixtures!$I$2:$I$2102,"A")) -> 41870 | I25: 2014/15 | J25: Aug 2014 home leg believed played at Atatürk Olympic Stadium (Inönü being rebuilt) — verify.
A26: Birmingham City | B26: Birmingham City | C26: =COUNTIF(Fixtures!$H$2:$H$2102,A26) -> 16 | D26: =COUNTIFS(Fixtures!$H$2:$H$2102,A26,Fixtures!$I$2:$I$2102,"H") -> 8 | E26: =COUNTIFS(Fixtures!$H$2:$H$2102,A26,Fixtures!$I$2:$I$2102,"A") -> 7 | F26: =COUNTIFS(Fixtures!$H$2:$H$2102,A26,Fixtures!$I$2:$I$2102,"N") -> 1 | G26: =IF(E26=0,"",_xlfn.MINIFS(Fixtures!$A$2:$A$2102,Fixtures!$H$2:$H$2102,A26,Fixtures!$I$2:$I$2102,"A")) -> 37633 | H26: =IF(E26=0,"",_xlfn.MAXIFS(Fixtures!$A$2:$A$2102,Fixtures!$H$2:$H$2102,A26,Fixtures!$I$2:$I$2102,"A")) -> 40544 | I26: 2002/03, 2003/04, 2004/05, 2005/06, 2007/08, 2009/10, 2010/11
A27: Blackburn Rovers | B27: Blackburn Rovers | C27: =COUNTIF(Fixtures!$H$2:$H$2102,A27) -> 43 | D27: =COUNTIFS(Fixtures!$H$2:$H$2102,A27,Fixtures!$I$2:$I$2102,"H") -> 21 | E27: =COUNTIFS(Fixtures!$H$2:$H$2102,A27,Fixtures!$I$2:$I$2102,"A") -> 21 | F27: =COUNTIFS(Fixtures!$H$2:$H$2102,A27,Fixtures!$I$2:$I$2102,"N") -> 1 | G27: =IF(E27=0,"",_xlfn.MINIFS(Fixtures!$A$2:$A$2102,Fixtures!$H$2:$H$2102,A27,Fixtures!$I$2:$I$2102,"A")) -> 33834 | H27: =IF(E27=0,"",_xlfn.MAXIFS(Fixtures!$A$2:$A$2102,Fixtures!$H$2:$H$2102,A27,Fixtures!$I$2:$I$2102,"A")) -> 40803 | I27: 1992/93, 1993/94, 1994/95, 1995/96, 1996/97, 1997/98, 1998/99, 2001/02, 2002/03, 2003/04, 2004/05, 2005/06, 2006/07, 2007/08, 2008/09, 2009/10, 2010/11, 2011/12
A28: Blackpool | B28: Blackpool | C28: =COUNTIF(Fixtures!$H$2:$H$2102,A28) -> 5 | D28: =COUNTIFS(Fixtures!$H$2:$H$2102,A28,Fixtures!$I$2:$I$2102,"H") -> 3 | E28: =COUNTIFS(Fixtures!$H$2:$H$2102,A28,Fixtures!$I$2:$I$2102,"A") -> 2 | F28: =COUNTIFS(Fixtures!$H$2:$H$2102,A28,Fixtures!$I$2:$I$2102,"N") -> 0 | G28: =IF(E28=0,"",_xlfn.MINIFS(Fixtures!$A$2:$A$2102,Fixtures!$H$2:$H$2102,A28,Fixtures!$I$2:$I$2102,"A")) -> 40643 | H28: =IF(E28=0,"",_xlfn.MAXIFS(Fixtures!$A$2:$A$2102,Fixtures!$H$2:$H$2102,A28,Fixtures!$I$2:$I$2102,"A")) -> 43470 | I28: 2010/11, 2018/19
A29: Bolton Wanderers | B29: Bolton Wanderers | C29: =COUNTIF(Fixtures!$H$2:$H$2102,A29) -> 34 | D29: =COUNTIFS(Fixtures!$H$2:$H$2102,A29,Fixtures!$I$2:$I$2102,"H") -> 17 | E29: =COUNTIFS(Fixtures!$H$2:$H$2102,A29,Fixtures!$I$2:$I$2102,"A") -> 17 | F29: =COUNTIFS(Fixtures!$H$2:$H$2102,A29,Fixtures!$I$2:$I$2102,"N") -> 0 | G29: =IF(E29=0,"",_xlfn.MINIFS(Fixtures!$A$2:$A$2102,Fixtures!$H$2:$H$2102,A29,Fixtures!$I$2:$I$2102,"A")) -> 34365 | H29: =IF(E29=0,"",_xlfn.MAXIFS(Fixtures!$A$2:$A$2102,Fixtures!$H$2:$H$2102,A29,Fixtures!$I$2:$I$2102,"A")) -> 40940 | I29: 1993/94, 1995/96, 1997/98, 2001/02, 2002/03, 2003/04, 2004/05, 2005/06, 2006/07, 2007/08, 2008/09, 2009/10, 2010/11, 2011/12 | J29: Burnden Park until 1996/97; Reebok Stadium (now Toughsheet) from 1997/98.
A30: Borussia Dortmund | B30: Borussia Dortmund | C30: =COUNTIF(Fixtures!$H$2:$H$2102,A30) -> 8 | D30: =COUNTIFS(Fixtures!$H$2:$H$2102,A30,Fixtures!$I$2:$I$2102,"H") -> 4 | E30: =COUNTIFS(Fixtures!$H$2:$H$2102,A30,Fixtures!$I$2:$I$2102,"A") -> 4 | F30: =COUNTIFS(Fixtures!$H$2:$H$2102,A30,Fixtures!$I$2:$I$2102,"N") -> 0 | G30: =IF(E30=0,"",_xlfn.MINIFS(Fixtures!$A$2:$A$2102,Fixtures!$H$2:$H$2102,A30,Fixtures!$I$2:$I$2102,"A")) -> 37559 | H30: =IF(E30=0,"",_xlfn.MAXIFS(Fixtures!$A$2:$A$2102,Fixtures!$H$2:$H$2102,A30,Fixtures!$I$2:$I$2102,"A")) -> 41898 | I30: 2002/03, 2011/12, 2013/14, 2014/15
A31: Borussia Mönchengladbach | B31: Borussia Mönchengladbach | C31: =COUNTIF(Fixtures!$H$2:$H$2102,A31) -> 2 | D31: =COUNTIFS(Fixtures!$H$2:$H$2102,A31,Fixtures!$I$2:$I$2102,"H") -> 1 | E31: =COUNTIFS(Fixtures!$H$2:$H$2102,A31,Fixtures!$I$2:$I$2102,"A") -> 1 | F31: =COUNTIFS(Fixtures!$H$2:$H$2102,A31,Fixtures!$I$2:$I$2102,"N") -> 0 | G31: =IF(E31=0,"",_xlfn.MINIFS(Fixtures!$A$2:$A$2102,Fixtures!$H$2:$H$2102,A31,Fixtures!$I$2:$I$2102,"A")) -> 35333 | H31: =IF(E31=0,"",_xlfn.MAXIFS(Fixtures!$A$2:$A$2102,Fixtures!$H$2:$H$2102,A31,Fixtures!$I$2:$I$2102,"A")) -> 35333 | I31: 1996/97
A32: Bradford City | B32: Bradford City | C32: =COUNTIF(Fixtures!$H$2:$H$2102,A32) -> 5 | D32: =COUNTIFS(Fixtures!$H$2:$H$2102,A32,Fixtures!$I$2:$I$2102,"H") -> 2 | E32: =COUNTIFS(Fixtures!$H$2:$H$2102,A32,Fixtures!$I$2:$I$2102,"A") -> 3 | F32: =COUNTIFS(Fixtures!$H$2:$H$2102,A32,Fixtures!$I$2:$I$2102,"N") -> 0 | G32: =IF(E32=0,"",_xlfn.MINIFS(Fixtures!$A$2:$A$2102,Fixtures!$H$2:$H$2102,A32,Fixtures!$I$2:$I$2102,"A")) -> 36561 | H32: =IF(E32=0,"",_xlfn.MAXIFS(Fixtures!$A$2:$A$2102,Fixtures!$H$2:$H$2102,A32,Fixtures!$I$2:$I$2102,"A")) -> 41254 | I32: 1999/00, 2000/01, 2012/13
A33: Brentford | B33: Brentford | C33: =COUNTIF(Fixtures!$H$2:$H$2102,A33) -> 12 | D33: =COUNTIFS(Fixtures!$H$2:$H$2102,A33,Fixtures!$I$2:$I$2102,"H") -> 6 | E33: =COUNTIFS(Fixtures!$H$2:$H$2102,A33,Fixtures!$I$2:$I$2102,"A") -> 6 | F33: =COUNTIFS(Fixtures!$H$2:$H$2102,A33,Fixtures!$I$2:$I$2102,"N") -> 0 | G33: =IF(E33=0,"",_xlfn.MINIFS(Fixtures!$A$2:$A$2102,Fixtures!$H$2:$H$2102,A33,Fixtures!$I$2:$I$2102,"A")) -> 44421 | H33: =IF(E33=0,"",_xlfn.MAXIFS(Fixtures!$A$2:$A$2102,Fixtures!$H$2:$H$2102,A33,Fixtures!$I$2:$I$2102,"A")) -> 46065 | I33: 2021/22, 2022/23, 2023/24, 2024/25, 2025/26
A34: Brighton and Hove Albion | B34: Brighton and Hove Albion | C34: =COUNTIF(Fixtures!$H$2:$H$2102,A34) -> 22 | D34: =COUNTIFS(Fixtures!$H$2:$H$2102,A34,Fixtures!$I$2:$I$2102,"H") -> 11 | E34: =COUNTIFS(Fixtures!$H$2:$H$2102,A34,Fixtures!$I$2:$I$2102,"A") -> 11 | F34: =COUNTIFS(Fixtures!$H$2:$H$2102,A34,Fixtures!$I$2:$I$2102,"N") -> 0 | G34: =IF(E34=0,"",_xlfn.MINIFS(Fixtures!$A$2:$A$2102,Fixtures!$H$2:$H$2102,A34,Fixtures!$I$2:$I$2102,"A")) -> 41300 | H34: =IF(E34=0,"",_xlfn.MAXIFS(Fixtures!$A$2:$A$2102,Fixtures!$H$2:$H$2102,A34,Fixtures!$I$2:$I$2102,"A")) -> 46085 | I34: 2012/13, 2014/15, 2017/18, 2018/19, 2019/20, 2020/21, 2021/22, 2022/23, 2023/24, 2024/25, 2025/26
A35: Brøndby | B35: Brøndby | C35: =COUNTIF(Fixtures!$H$2:$H$2102,A35) -> 2 | D35: =COUNTIFS(Fixtures!$H$2:$H$2102,A35,Fixtures!$I$2:$I$2102,"H") -> 1 | E35: =COUNTIFS(Fixtures!$H$2:$H$2102,A35,Fixtures!$I$2:$I$2102,"A") -> 1 | F35: =COUNTIFS(Fixtures!$H$2:$H$2102,A35,Fixtures!$I$2:$I$2102,"N") -> 0 | G35: =IF(E35=0,"",_xlfn.MINIFS(Fixtures!$A$2:$A$2102,Fixtures!$H$2:$H$2102,A35,Fixtures!$I$2:$I$2102,"A")) -> 34627 | H35: =IF(E35=0,"",_xlfn.MAXIFS(Fixtures!$A$2:$A$2102,Fixtures!$H$2:$H$2102,A35,Fixtures!$I$2:$I$2102,"A")) -> 34627 | I35: 1994/95
A36: Burnley | B36: Burnley | C36: =COUNTIF(Fixtures!$H$2:$H$2102,A36) -> 24 | D36: =COUNTIFS(Fixtures!$H$2:$H$2102,A36,Fixtures!$I$2:$I$2102,"H") -> 12 | E36: =COUNTIFS(Fixtures!$H$2:$H$2102,A36,Fixtures!$I$2:$I$2102,"A") -> 12 | F36: =COUNTIFS(Fixtures!$H$2:$H$2102,A36,Fixtures!$I$2:$I$2102,"N") -> 0 | G36: =IF(E36=0,"",_xlfn.MINIFS(Fixtures!$A$2:$A$2102,Fixtures!$H$2:$H$2102,A36,Fixtures!$I$2:$I$2102,"A")) -> 39453 | H36: =IF(E36=0,"",_xlfn.MAXIFS(Fixtures!$A$2:$A$2102,Fixtures!$H$2:$H$2102,A36,Fixtures!$I$2:$I$2102,"A")) -> 45962 | I36: 2007/08, 2008/09, 2009/10, 2014/15, 2016/17, 2017/18, 2018/19, 2019/20, 2020/21, 2021/22, 2023/24, 2025/26
A37: Cambridge United | B37: Cambridge United | C37: =COUNTIF(Fixtures!$H$2:$H$2102,A37) -> 1 | D37: =COUNTIFS(Fixtures!$H$2:$H$2102,A37,Fixtures!$I$2:$I$2102,"H") -> 1 | E37: =COUNTIFS(Fixtures!$H$2:$H$2102,A37,Fixtures!$I$2:$I$2102,"A") -> 0 | F37: =COUNTIFS(Fixtures!$H$2:$H$2102,A37,Fixtures!$I$2:$I$2102,"N") -> 0 | G37: =IF(E37=0,"",_xlfn.MINIFS(Fixtures!$A$2:$A$2102,Fixtures!$H$2:$H$2102,A37,Fixtures!$I$2:$I$2102,"A")) | H37: =IF(E37=0,"",_xlfn.MAXIFS(Fixtures!$A$2:$A$2102,Fixtures!$H$2:$H$2102,A37,Fixtures!$I$2:$I$2102,"A"))
A38: Cardiff City | B38: Cardiff City | C38: =COUNTIF(Fixtures!$H$2:$H$2102,A38) -> 7 | D38: =COUNTIFS(Fixtures!$H$2:$H$2102,A38,Fixtures!$I$2:$I$2102,"H") -> 4 | E38: =COUNTIFS(Fixtures!$H$2:$H$2102,A38,Fixtures!$I$2:$I$2102,"A") -> 3 | F38: =COUNTIFS(Fixtures!$H$2:$H$2102,A38,Fixtures!$I$2:$I$2102,"N") -> 0 | G38: =IF(E38=0,"",_xlfn.MINIFS(Fixtures!$A$2:$A$2102,Fixtures!$H$2:$H$2102,A38,Fixtures!$I$2:$I$2102,"A")) -> 39838 | H38: =IF(E38=0,"",_xlfn.MAXIFS(Fixtures!$A$2:$A$2102,Fixtures!$H$2:$H$2102,A38,Fixtures!$I$2:$I$2102,"A")) -> 43345 | I38: 2008/09, 2013/14, 2018/19 | J38: Ninian Park for 2008/09 (FA Cup); Cardiff City Stadium from 2009.
A39: Carlisle United | B39: Carlisle United | C39: =COUNTIF(Fixtures!$H$2:$H$2102,A39) -> 1 | D39: =COUNTIFS(Fixtures!$H$2:$H$2102,A39,Fixtures!$I$2:$I$2102,"H") -> 0 | E39: =COUNTIFS(Fixtures!$H$2:$H$2102,A39,Fixtures!$I$2:$I$2102,"A") -> 1 | F39: =COUNTIFS(Fixtures!$H$2:$H$2102,A39,Fixtures!$I$2:$I$2102,"N") -> 0 | G39: =IF(E39=0,"",_xlfn.MINIFS(Fixtures!$A$2:$A$2102,Fixtures!$H$2:$H$2102,A39,Fixtures!$I$2:$I$2102,"A")) -> 36897 | H39: =IF(E39=0,"",_xlfn.MAXIFS(Fixtures!$A$2:$A$2102,Fixtures!$H$2:$H$2102,A39,Fixtures!$I$2:$I$2102,"A")) -> 36897 | I39: 2000/01
A40: Celta Vigo | B40: Celta Vigo | C40: =COUNTIF(Fixtures!$H$2:$H$2102,A40) -> 2 | D40: =COUNTIFS(Fixtures!$H$2:$H$2102,A40,Fixtures!$I$2:$I$2102,"H") -> 1 | E40: =COUNTIFS(Fixtures!$H$2:$H$2102,A40,Fixtures!$I$2:$I$2102,"A") -> 1 | F40: =COUNTIFS(Fixtures!$H$2:$H$2102,A40,Fixtures!$I$2:$I$2102,"N") -> 0 | G40: =IF(E40=0,"",_xlfn.MINIFS(Fixtures!$A$2:$A$2102,Fixtures!$H$2:$H$2102,A40,Fixtures!$I$2:$I$2102,"A")) -> 38041 | H40: =IF(E40=0,"",_xlfn.MAXIFS(Fixtures!$A$2:$A$2102,Fixtures!$H$2:$H$2102,A40,Fixtures!$I$2:$I$2102,"A")) -> 38041 | I40: 2003/04
...

Sheet Away matches
A1: Opponent | B1: Date | C1: Season | D1: Competition | E1: Match | F1: Score
A2: 1.FC Köln | B2: 43062 | C2: 2017/18 | D2: UEFA Europa League | E2: 1.FC Köln v Arsenal | F2: 1-0
A3: AC Milan | B3: 34738 | C3: 1994/95 | D3: UEFA Super Cup | E3: AC Milan v Arsenal | F3: 2-0
A4: AC Milan | B4: 39511 | C4: 2007/08 | D4: UEFA Champions League | E4: AC Milan v Arsenal | F4: 0-2
A5: AC Milan | B5: 40954 | C5: 2011/12 | D5: UEFA Champions League | E5: AC Milan v Arsenal | F5: 4-0
A6: AC Milan | B6: 43167 | C6: 2017/18 | D6: UEFA Europa League | E6: AC Milan v Arsenal | F6: 0-2
A7: AFC Bournemouth | B7: 42407 | C7: 2015/16 | D7: Premier League | E7: AFC Bournemouth v Arsenal | F7: 0-2
A8: AFC Bournemouth | B8: 42738 | C8: 2016/17 | D8: Premier League | E8: AFC Bournemouth v Arsenal | F8: 3-3
A9: AFC Bournemouth | B9: 43114 | C9: 2017/18 | D9: Premier League | E9: AFC Bournemouth v Arsenal | F9: 2-1
A10: AFC Bournemouth | B10: 43429 | C10: 2018/19 | D10: Premier League | E10: AFC Bournemouth v Arsenal | F10: 1-2
A11: AFC Bournemouth | B11: 43825 | C11: 2019/20 | D11: Premier League | E11: AFC Bournemouth v Arsenal | F11: 1-1
A12: AFC Bournemouth | B12: 43857 | C12: 2019/20 | D12: FA Cup | E12: AFC Bournemouth v Arsenal | F12: 1-2
A13: AFC Bournemouth | B13: 44793 | C13: 2022/23 | D13: Premier League | E13: AFC Bournemouth v Arsenal | F13: 0-3
... A1023: Östersunds FK | B1023: 43146 | C1023: 2017/18 | D1023: UEFA Europa League | E1023: Östersunds FK v Arsenal | F1023: 0-3

Sheet Grounds template
A1: How to use: one row per ground per club per period. Fill the yellow columns. "Used to" blank = still in use. Row 5 is an example (Highbury coordinates approximate).
A3: Ground ID | B3: Ground name | C3: Club (as in Fixtures) | D3: Used from | E3: Used to | F3: Latitude | G3: Longitude | H3: City | I3: Country | J3: Notes
A5: G001 | B5: Highbury | C5: Arsenal | D5: 4998 | E5: 38844 | F5: 51.558 | G5: -0.103 | H5: London | I5: England | J5: EXAMPLE ROW — coordinates approximate
A6: G002 | B6: Emirates Stadium | C6: Arsenal | D6: 38920 | H6: London | I6: England
A7: G003 | B7: Wembley Stadium | C7: Arsenal | H7: London | I7: England | J7: Arsenal home CL games 1998/99–1999/00; also neutral venue. Old vs new Wembley (rebuilt 2003–07) sit on the same site.
A8: G004 | B8: Millennium Stadium | C8: (neutral) | H8: Cardiff | I8: Wales | J8: Spelt "Millenium Stadium" in Fixtures sheet — align spelling.
A9: G005 | B9: Villa Park | C9: Aston Villa | H9: Birmingham | I9: England | J9: Also neutral venue for FA Cup semis.
A10: G006 | B10: Old Trafford | C10: Manchester United | H10: Manchester | I10: England | J10: Also neutral venue for FA Cup semis.
A11: G007 | B11: Parken Stadium | C11: (neutral) | H11: Copenhagen | I11: Denmark
A12: G008 | B12: Parc des Princes | C12: Paris St Germain | H12: Paris | I12: France | J12: Also 1995 CWC final venue.
A13: G009 | B13: Stade de France | C13: (neutral) | H13: Saint-Denis | I13: France
A14: G010 | B14: Baku Olympic Stadium | C14: (neutral) | H14: Baku | I14: Azerbaijan
A15: G011 | B15: Puskás Aréna | C15: (neutral) | H15: Budapest | I15: Hungary
A16: G012 | B16: Stadio Olimpico | C16: Benfica (2021 only) | H16: Rome | I16: Italy | J16: Benfica v Arsenal, 18/02/2021.
A17: G013 | B17: Karaiskakis Stadium | C17: Arsenal (2021 only) | H17: Piraeus | I17: Greece | J17: Arsenal v Benfica, 25/02/2021. Also Olympiakos home.

Sheet Flags to check
A1: Type | B1: Date | C1: Match | D1: Venue in data | E1: Suggested venue | F1: Confidence | G1: Note
A2: Neutral venue not marked | B2: 32732 | C2: Liverpool v Arsenal | E2: Wembley | F2: High | G2: Charity/Community Shield — always a neutral venue.
A3: Neutral venue not marked | B3: 33460 | C3: Arsenal v Tottenham Hotspur | E3: Wembley | F3: High | G3: Charity/Community Shield — always a neutral venue.
A4: Neutral venue not marked | B4: 34188 | C4: Arsenal v Manchester United | E4: Wembley | F4: High | G4: Charity/Community Shield — always a neutral venue.
A5: Neutral venue not marked | B5: 36016 | C5: Arsenal v Manchester United | E5: Wembley | F5: High | G5: Charity/Community Shield — always a neutral venue.
A6: Neutral venue not marked | B6: 36373 | C6: Arsenal v Manchester United | E6: Wembley | F6: High | G6: Charity/Community Shield — always a neutral venue.
A7: Neutral venue not marked | B7: 45144 | C7: Arsenal v Manchester City | E7: Wembley | F7: High | G7: Charity/Community Shield — always a neutral venue.
A8: Arsenal home not at Highbury | B8: 36068 | C8: Arsenal v Panathinaikos | E8: Wembley | F8: High | G8: Arsenal played CL home games at Wembley in 1998/99 and 1999/00.
A9: Arsenal home not at Highbury | B9: 36089 | C9: Arsenal v Dynamo Kiev | E9: Wembley | F9: High | G9: Arsenal played CL home games at Wembley in 1998/99 and 1999/00.
A10: Arsenal home not at Highbury | B10: 36124 | C10: Arsenal v RC Lens | E10: Wembley | F10: High | G10: Arsenal played CL home games at Wembley in 1998/99 and 1999/00.
A11: Arsenal home not at Highbury | B11: 36425 | C11: Arsenal v AIK Solna | E11: Wembley | F11: High | G11: Arsenal played CL home games at Wembley in 1998/99 and 1999/00.
A12: Arsenal home not at Highbury | B12: 36452 | C12: Arsenal v Barcelona | E12: Wembley | F12: High | G12: Arsenal played CL home games at Wembley in 1998/99 and 1999/00.
A13: Arsenal home not at Highbury | B13: 36460 | C13: Arsenal v Fiorentina | E13: Wembley | F13: High | G13: Arsenal played CL home games at Wembley in 1998/99 and 1999/00.
... A27: Temporary home ground | B27: 38116 | C27: Fulham v Arsenal | E27: Loftus Road | F27: High | G27: Fulham at Loftus Road 2002–04. Handled by grounds date ranges.
A28: Spelling | C28: All Millennium Stadium rows | D28: Millenium Stadium | E28: Millennium Stadium | F28: High | G28: Align with the grounds sheet name.
A29: Result convention | C29: 23 matches decided on penalties | F29: — | G29: Result column records the shoot-out outcome (e.g. 1-1 (4-5) = L). Decide whether stats count these as W/L or D.
A30: Duplicate team names | C30: 6 pairs | F30: High | G30: See "Suggested merged name" on Opponents sheet (e.g. Bayern Munchen / München).

Sheet Fixtures
A1: Date | B1: Match | C1: Result | D1: Score | E1: Competition | F1: Venue | G1: Season | H1: Opponent | I1: H/A/N | J1: Behind closed doors
A2: 32382 | B2: Wimbledon v Arsenal | C2: W | D2: 1-5 | E2: League Division One | G2: 1988/89 | H2: =IF(LEFT(B2,10)="Arsenal v ",MID(B2,11,100),LEFT(B2,FIND(" v ",B2)-1)) -> Wimbledon | I2: =IF(F2<>"","N",IF(LEFT(B2,10)="Arsenal v ","H","A")) -> A
A3: 32389 | B3: Arsenal v Aston Villa | C3: L | D3: 2-3 | E3: League Division One | G3: 1988/89 | H3: =IF(LEFT(B3,10)="Arsenal v ",MID(B3,11,100),LEFT(B3,FIND(" v ",B3)-1)) -> Aston Villa | I3: =IF(F3<>"","N",IF(LEFT(B3,10)="Arsenal v ","H","A")) -> H
A4: 32396 | B4: Tottenham Hotspur v Arsenal | C4: W | D4: 2-3 | E4: League Division One | G4: 1988/89 | H4: =IF(LEFT(B4,10)="Arsenal v ",MID(B4,11,100),LEFT(B4,FIND(" v ",B4)-1)) -> Tottenham Hotspur | I4: =IF(F4<>"","N",IF(LEFT(B4,10)="Arsenal v ","H","A")) -> A
A5: 32403 | B5: Arsenal v Southampton | C5: D | D5: 2-2 | E5: League Division One | G5: 1988/89 | H5: =IF(LEFT(B5,10)="Arsenal v ",MID(B5,11,100),LEFT(B5,FIND(" v ",B5)-1)) -> Southampton | I5: =IF(F5<>"","N",IF(LEFT(B5,10)="Arsenal v ","H","A")) -> H
A6: 32410 | B6: Sheffield Wednesday v Arsenal | C6: L | D6: 2-1 | E6: League Division One | G6: 1988/89 | H6: =IF(LEFT(B6,10)="Arsenal v ",MID(B6,11,100),LEFT(B6,FIND(" v ",B6)-1)) -> Sheffield Wednesday | I6: =IF(F6<>"","N",IF(LEFT(B6,10)="Arsenal v ","H","A")) -> A
A7: 32414 | B7: Hull City v Arsenal | C7: W | D7: 1-2 | E7: League Cup | G7: 1988/89 | H7: =IF(LEFT(B7,10)="Arsenal v ",MID(B7,11,100),LEFT(B7,FIND(" v ",B7)-1)) -> Hull City | I7: =IF(F7<>"","N",IF(LEFT(B7,10)="Arsenal v ","H","A")) -> A
A8: 32417 | B8: West Ham United v Arsenal | C8: W | D8: 1-4 | E8: League Division One | G8: 1988/89 | H8: =IF(LEFT(B8,10)="Arsenal v ",MID(B8,11,100),LEFT(B8,FIND(" v ",B8)-1)) -> West Ham United | I8: =IF(F8<>"","N",IF(LEFT(B8,10)="Arsenal v ","H","A")) -> A
A9: 32428 | B9: Arsenal v Hull City | C9: W | D9: 3-0 | E9: League Cup | G9: 1988/89 | H9: =IF(LEFT(B9,10)="Arsenal v ",MID(B9,11,100),LEFT(B9,FIND(" v ",B9)-1)) -> Hull City | I9: =IF(F9<>"","N",IF(LEFT(B9,10)="Arsenal v ","H","A")) -> H
A10: 32438 | B10: Arsenal v Queens Park Rangers | C10: W | D10: 2-1 | E10: League Division One | G10: 1988/89 | H10: =IF(LEFT(B10,10)="Arsenal v ",MID(B10,11,100),LEFT(B10,FIND(" v ",B10)-1)) -> Queens Park Rangers | I10: =IF(F10<>"","N",IF(LEFT(B10,10)="Arsenal v ","H","A")) -> H
A11: 32441 | B11: Luton Town v Arsenal | C11: D | D11: 1-1 | E11: League Division One | G11: 1988/89 | H11: =IF(LEFT(B11,10)="Arsenal v ",MID(B11,11,100),LEFT(B11,FIND(" v ",B11)-1)) -> Luton Town | I11: =IF(F11<>"","N",IF(LEFT(B11,10)="Arsenal v ","H","A")) -> A
A12: 32445 | B12: Arsenal v Coventry City | C12: W | D12: 2-0 | E12: League Division One | G12: 1988/89 | H12: =IF(LEFT(B12,10)="Arsenal v ",MID(B12,11,100),LEFT(B12,FIND(" v ",B12)-1)) -> Coventry City | I12: =IF(F12<>"","N",IF(LEFT(B12,10)="Arsenal v ","H","A")) -> H
A13: 32449 | B13: Liverpool v Arsenal | C13: D | D13: 1-1 | E13: League Cup | G13: 1988/89 | H13: =IF(LEFT(B13,10)="Arsenal v ",MID(B13,11,100),LEFT(B13,FIND(" v ",B13)-1)) -> Liverpool | I13: =IF(F13<>"","N",IF(LEFT(B13,10)="Arsenal v ","H","A")) -> A
... A137: 33337 | B137: Southampton v Arsenal | C137: D | D137: 1-1 | E137: League Division One | G137: 1990/91 | H137: =IF(LEFT(B137,10)="Arsenal v ",MID(B137,11,100),LEFT(B137,FIND(" v ",B137)-1)) -> Southampton | I137: =IF(F137<>"","N",IF(LEFT(B137,10)="Arsenal v ","H","A")) -> A
A138: 33342 | B138: Tottenham Hotspur v Arsenal | C138: L | D138: 3-1 | E138: FA Cup | F138: Wembley | G138: 1990/91 | H138: =IF(LEFT(B138,10)="Arsenal v ",MID(B138,11,100),LEFT(B138,FIND(" v ",B138)-1)) -> Tottenham Hotspur | I138: =IF(F138<>"","N",IF(LEFT(B138,10)="Arsenal v ","H","A")) -> N
A139: 33345 | B139: Arsenal v Manchester City | C139: D | D139: 2-2 | E139: League Division One | G139: 1990/91 | H139: =IF(LEFT(B139,10)="Arsenal v ",MID(B139,11,100),LEFT(B139,FIND(" v ",B139)-1)) -> Manchester City | I139: =IF(F139<>"","N",IF(LEFT(B139,10)="Arsenal v ","H","A")) -> H
A140: 33351 | B140: Arsenal v Queens Park Rangers | C140: W | D140: 2-0 | E140: League Division One | G140: 1990/91 | H140: =IF(LEFT(B140,10)="Arsenal v ",MID(B140,11,100),LEFT(B140,FIND(" v ",B140)-1)) -> Queens Park Rangers | I140: =IF(F140<>"","N",IF(LEFT(B140,10)="Arsenal v ","H","A")) -> H
A141: 33362 | B141: Sunderland v Arsenal | C141: D | D141: 0-0 | E141: League Division One | G141: 1990/91 | H141: =IF(LEFT(B141,10)="Arsenal v ",MID(B141,11,100),LEFT(B141,FIND(" v ",B141)-1)) -> Sunderland | I141: =IF(F141<>"","N",IF(LEFT(B141,10)="Arsenal v ","H","A")) -> A
A142: 33364 | B142: Arsenal v Manchester United | C142: W | D142: 3-1 | E142: League Division One | G142: 1990/91 | H142: =IF(LEFT(B142,10)="Arsenal v ",MID(B142,11,100),LEFT(B142,FIND(" v ",B142)-1)) -> Manchester United | I142: =IF(F142<>"","N",IF(LEFT(B142,10)="Arsenal v ","H","A")) -> H
A143: 33369 | B143: Arsenal v Coventry City | C143: W | D143: 6-1 | E143: League Division One | G143: 1990/91 | H143: =IF(LEFT(B143,10)="Arsenal v ",MID(B143,11,100),LEFT(B143,FIND(" v ",B143)-1)) -> Coventry City | I143: =IF(F143<>"","N",IF(LEFT(B143,10)="Arsenal v ","H","A")) -> H
A144: 33460 | B144: Arsenal v Tottenham Hotspur | C144: D | D144: 0-0 | E144: FA Charity Shield | G144: 1991/92 | H144: =IF(LEFT(B144,10)="Arsenal v ",MID(B144,11,100),LEFT(B144,FIND(" v ",B144)-1)) -> Tottenham Hotspur | I144: =IF(F144<>"","N",IF(LEFT(B144,10)="Arsenal v ","H","A")) -> H
A145: 33467 | B145: Arsenal v Queens Park Rangers | C145: D | D145: 1-1 | E145: League Division One | G145: 1991/92 | H145: =IF(LEFT(B145,10)="Arsenal v ",MID(B145,11,100),LEFT(B145,FIND(" v ",B145)-1)) -> Queens Park Rangers | I145: =IF(F145<>"","N",IF(LEFT(B145,10)="Arsenal v ","H","A")) -> H
A146: 33470 | B146: Everton v Arsenal | C146: L | D146: 3-1 | E146: League Division One | G146: 1991/92 | H146: =IF(LEFT(B146,10)="Arsenal v ",MID(B146,11,100),LEFT(B146,FIND(" v ",B146)-1)) -> Everton | I146: =IF(F146<>"","N",IF(LEFT(B146,10)="Arsenal v ","H","A")) -> A
A147: 33474 | B147: Aston Villa v Arsenal | C147: L | D147: 3-1 | E147: League Division One | G147: 1991/92 | H147: =IF(LEFT(B147,10)="Arsenal v ",MID(B147,11,100),LEFT(B147,FIND(" v ",B147)-1)) -> Aston Villa | I147: =IF(F147<>"","N",IF(LEFT(B147,10)="Arsenal v ","H","A")) -> A
A148: 33477 | B148: Arsenal v Luton Town | C148: W | D148: 2-0 | E148: League Division One | G148: 1991/92 | H148: =IF(LEFT(B148,10)="Arsenal v ",MID(B148,11,100),LEFT(B148,FIND(" v ",B148)-1)) -> Luton Town | I148: =IF(F148<>"","N",IF(LEFT(B148,10)="Arsenal v ","H","A")) -> H
A149: 33481 | B149: Arsenal v Manchester City | C149: W | D149: 2-1 | E149: League Division One | G149: 1991/92 | H149: =IF(LEFT(B149,10)="Arsenal v ",MID(B149,11,100),LEFT(B149,FIND(" v ",B149)-1)) -> Manchester City | I149: =IF(F149<>"","N",IF(LEFT(B149,10)="Arsenal v ","H","A")) -> H
A150: 33484 | B150: Leeds United v Arsenal | C150: D | D150: 2-2 | E150: League Division One | G150: 1991/92 | H150: =IF(LEFT(B150,10)="Arsenal v ",MID(B150,11,100),LEFT(B150,FIND(" v ",B150)-1)) -> Leeds United | I150: =IF(F150<>"","N",IF(LEFT(B150,10)="Arsenal v ","H","A")) -> A
... A240: 34052 | B240: Manchester United v Arsenal | C240: D | D240: 0-0 | E240: Premier League | G240: 1992/93 | H240: =IF(LEFT(B240,10)="Arsenal v ",MID(B240,11,100),LEFT(B240,FIND(" v ",B240)-1)) -> Manchester United | I240: =IF(F240<>"","N",IF(LEFT(B240,10)="Arsenal v ","H","A")) -> A
A241: 34063 | B241: Arsenal v Tottenham Hotspur | C241: W | D241: 1-0 | E241: FA Cup | F241: Wembley | G241: 1992/93 | H241: =IF(LEFT(B241,10)="Arsenal v ",MID(B241,11,100),LEFT(B241,FIND(" v ",B241)-1)) -> Tottenham Hotspur | I241: =IF(F241<>"","N",IF(LEFT(B241,10)="Arsenal v ","H","A")) -> N
A242: 34065 | B242: Middlesbrough v Arsenal | C242: L | D242: 1-0 | E242: Premier League | G242: 1992/93 | H242: =IF(LEFT(B242,10)="Arsenal v ",MID(B242,11,100),LEFT(B242,FIND(" v ",B242)-1)) -> Middlesbrough | I242: =IF(F242<>"","N",IF(LEFT(B242,10)="Arsenal v ","H","A")) -> A
A243: 34069 | B243: Ipswich Town v Arsenal | C243: W | D243: 1-2 | E243: Premier League | G243: 1992/93 | H243: =IF(LEFT(B243,10)="Arsenal v ",MID(B243,11,100),LEFT(B243,FIND(" v ",B243)-1)) -> Ipswich Town | I243: =IF(F243<>"","N",IF(LEFT(B243,10)="Arsenal v ","H","A")) -> A
A244: 34071 | B244: Arsenal v Aston Villa | C244: L | D244: 0-1 | E244: Premier League | G244: 1992/93 | H244: =IF(LEFT(B244,10)="Arsenal v ",MID(B244,11,100),LEFT(B244,FIND(" v ",B244)-1)) -> Aston Villa | I244: =IF(F244<>"","N",IF(LEFT(B244,10)="Arsenal v ","H","A")) -> H
A245: 34077 | B245: Arsenal v Sheffield Wednesday | C245: W | D245: 2-1 | E245: League Cup | F245: Wembley | G245: 1992/93 | H245: =IF(LEFT(B245,10)="Arsenal v ",MID(B245,11,100),LEFT(B245,FIND(" v ",B245)-1)) -> Sheffield Wednesday | I245: =IF(F245<>"","N",IF(LEFT(B245,10)="Arsenal v ","H","A")) -> N
A246: 34080 | B246: Arsenal v Nottingham Forest | C246: D | D246: 1-1 | E246: Premier League | G246: 1992/93 | H246: =IF(LEFT(B246,10)="Arsenal v ",MID(B246,11,100),LEFT(B246,FIND(" v ",B246)-1)) -> Nottingham Forest | I246: =IF(F246<>"","N",IF(LEFT(B246,10)="Arsenal v ","H","A")) -> H
A247: 34090 | B247: Everton v Arsenal | C247: D | D247: 0-0 | E247: Premier League | G247: 1992/93 | H247: =IF(LEFT(B247,10)="Arsenal v ",MID(B247,11,100),LEFT(B247,FIND(" v ",B247)-1)) -> Everton | I247: =IF(F247<>"","N",IF(LEFT(B247,10)="Arsenal v ","H","A")) -> A
A248: 34093 | B248: Arsenal v Queens Park Rangers | C248: D | D248: 0-0 | E248: Premier League | G248: 1992/93 | H248: =IF(LEFT(B248,10)="Arsenal v ",MID(B248,11,100),LEFT(B248,FIND(" v ",B248)-1)) -> Queens Park Rangers | I248: =IF(F248<>"","N",IF(LEFT(B248,10)="Arsenal v ","H","A")) -> H
A249: 34095 | B249: Sheffield Wednesday v Arsenal | C249: L | D249: 1-0 | E249: Premier League | G249: 1992/93 | H249: =IF(LEFT(B249,10)="Arsenal v ",MID(B249,11,100),LEFT(B249,FIND(" v ",B249)-1)) -> Sheffield Wednesday | I249: =IF(F249<>"","N",IF(LEFT(B249,10)="Arsenal v ","H","A")) -> A
A250: 34097 | B250: Arsenal v Crystal Palace | C250: W | D250: 3-0 | E250: Premier League | G250: 1992/93 | H250: =IF(LEFT(B250,10)="Arsenal v ",MID(B250,11,100),LEFT(B250,FIND(" v ",B250)-1)) -> Crystal Palace | I250: =IF(F250<>"","N",IF(LEFT(B250,10)="Arsenal v ","H","A")) -> H
A251: 34100 | B251: Arsenal v Tottenham Hotspur | C251: L | D251: 1-3 | E251: Premier League | G251: 1992/93 | H251: =IF(LEFT(B251,10)="Arsenal v ",MID(B251,11,100),LEFT(B251,FIND(" v ",B251)-1)) -> Tottenham Hotspur | I251: =IF(F251<>"","N",IF(LEFT(B251,10)="Arsenal v ","H","A")) -> H
A252: 34104 | B252: Arsenal v Sheffield Wednesday | C252: D | D252: 1-1 | E252: FA Cup | F252: Wembley | G252: 1992/93 | H252: =IF(LEFT(B252,10)="Arsenal v ",MID(B252,11,100),LEFT(B252,FIND(" v ",B252)-1)) -> Sheffield Wednesday | I252: =IF(F252<>"","N",IF(LEFT(B252,10)="Arsenal v ","H","A")) -> N
...
